package wallet

import (
	"testing"
)

func TestWallet(t *testing.T) {
	t.Run("deposit", func(t *testing.T) {
		wallet := Wallet{}
		wallet.Deposit(Bitcoin(10))
		assertBalance(t, wallet, Bitcoin(10))
	})

	t.Run("withdraw", func(t *testing.T) {
		wallet := Wallet{balance: Bitcoin(20)}
		wallet.Withdraw(Bitcoin(10))
		assertBalance(t, wallet, Bitcoin(10))
	})

	t.Run("withdraw insufficient funds", func(t *testing.T) {
		startingBalance := Bitcoin(20)
		wallet := Wallet{startingBalance}
		err := wallet.Withdraw(Bitcoin(100))

		assertError(t, err, ErrInsufficientFunds)
		assertBalance(t, wallet, startingBalance)
	})
}

func assertBalance(t testing.TB, wallet Wallet, want Bitcoin) {
	t.Helper()
	got := wallet.Balance()

	if got != want {
		t.Errorf("got %q, want %q", got, want)
	}
}

// We've introduced t.Fatal which will stop the test if it is called.
// This is because we don't want to make any more assertions on the error returned if there isn't one around.
// Without this the test would carry on to the next step and panic because of a nil pointer.
func assertError(t testing.TB, got, want error) {
	t.Helper()
	if got == nil {
		t.Fatal("didn't get an error but wanted one")
	}

	if got != want {
		t.Errorf("got %q, want %q", got, want)
	}
}
